Workbook

Sheet Index
A1: Table S1. Heat treatment DEGs in O. faveolata host -2>logFC>2; p<0.001
A2: Table S2. Heat treatment DEGs in O. faveolata host -2>logFC>2; p<0.01
A3: Table S3. Heat treatment DEGs in Symbiodinium A3 -2>logFC>2; p<0.001
A4: Table S4. Heat treatment DEGs in Symbiodinium A3 -2>logFC>2; p<0.01
A5: Table S5. Heat treatment DEGs in P. clivosa host -2>logFC>2; p<0.001
A6: Table S6. Heat treatment DEGs in P.clivosa host -2>logFC>2; p<0.01
A7: Table S7. Heat treatment DEGs in B. faviinorum -2>logFC>2; p<0.001
A8: Table S8. Heat treatment DEGs in B. faviinorum -2>logFC>2; p<0.01
A9: Table S9. Heat treatment DEGs in S. radians host -2>logFC>2; p<0.001
A10: Table S10. Heat treatment DEGs in S. radians host -2>logFC>2; p<0.01
A11: Table S11. Heat treatment DEGs in Breviolum B5 -2>logFC>2; p<0.001
A12: Table S12. Heat treatment DEGs in Breviolum B5 -2>logFC>2; p<0.01

Sheet TableS1
A1: Table S1 | Heat treatment DEGs in Orbicella faveolata host -2>logFC>2 padj<0.001. p value is obtained from a Wald test, and BH adjusted p-values are provided as padj (DESeq2).
A2: id | B2: baseMean | C2: log2FoldChange | D2: lfcSE | E2: stat | F2: pvalue | G2: padj | H2: KO | I2: Description | J2: GO
A3: TRINITY_DN133010_c0_g1 | B3: 268.5745 | C3: -25.110424 | D3: 4.7850673 | E3: -5.2476637 | F3: 1.5404015e-07 | G3: 3.8715618e-05 | H3: - | I3: - | J3: -
A4: TRINITY_DN209127_c0_g6 | B4: 42.653788 | C4: -9.216256 | D4: 1.5887831 | E4: -5.800827 | F4: 6.5988641e-09 | G4: 2.7746356e-06 | H4: - | I4: - | J4: -
A5: TRINITY_DN215574_c1_g1 | B5: 37.227242 | C5: -9.0821118 | D5: 1.5764716 | E5: -5.7610373 | F5: 8.3598548e-09 | G5: 3.3872612e-06 | H5: - | I5: - | J5: -
A6: TRINITY_DN214478_c0_g2 | B6: 20119.853 | C6: -9.0172137 | D6: 0.95707083 | E6: -9.4216786 | F6: 4.4393342e-21 | G6: 1.2903986e-17 | H6: - | I6: - | J6: -
A7: TRINITY_DN203261_c1_g1 | B7: 35.245765 | C7: -8.9771765 | D7: 1.5709409 | E7: -5.7145221 | F7: 1.1001276e-08 | G7: 4.2635012e-06 | H7: K06236 | I7: collagen | J7: -
A8: TRINITY_DN216889_c5_g2 | B8: 21217.981 | C8: -8.8854598 | D8: 0.97644837 | E8: -9.0997743 | F8: 9.051975e-20 | G8: 2.2413696e-16 | H8: - | I8: - | J8: -
A9: TRINITY_DN101348_c0_g2 | B9: 27.676423 | C9: -8.6186917 | D9: 1.5985006 | E9: -5.3917349 | F9: 6.9780656e-08 | G9: 2.0412064e-05 | H9: K19527 | I9: vacuolar sorting protein 13D | J9: -
A10: TRINITY_DN10408_c0_g3 | B10: 25.262238 | C10: -8.5124695 | D10: 1.611603 | E10: -5.2819892 | F10: 1.2778874e-07 | G10: 3.3113629e-05 | H10: - | I10: - | J10: -
A11: TRINITY_DN219930_c3_g13 | B11: 48.702017 | C11: -8.0379654 | D11: 1.5374638 | E11: -5.2280681 | F11: 1.7129045e-07 | G11: 4.2223765e-05 | H11: - | I11: - | J11: -
A12: TRINITY_DN82298_c0_g2 | B12: 488.75958 | C12: -8.0228644 | D12: 0.56707542 | E12: -14.147791 | F12: 1.9271676e-45 | G12: 2.5768158e-41 | H12: - | I12: - | J12: -
A13: TRINITY_DN332658_c0_g1 | B13: 853.28024 | C13: -7.8160198 | D13: 0.44626899 | E13: -17.514145 | F13: 1.1175236e-68 | G13: 7.4712041e-64 | H13: - | I13: - | J13: -
A14: TRINITY_DN68014_c0_g1 | B14: 1131.6922 | C14: -7.3204772 | D14: 1.0284064 | E14: -7.1182727 | F14: 1.0928795e-12 | G14: 1.1416322e-09 | H14: - | I14: - | J14: -
... A308: TRINITY_DN201178_c0_g1 | B308: 260.08825 | C308: 2.1854777 | D308: 0.44168954 | E308: 4.9479951 | F308: 7.4981792e-07 | G308: 0.0001509912 | H308: - | I308: - | J308: -
A309: TRINITY_DN180318_c0_g1 | B309: 121.94668 | C309: 2.1385791 | D309: 0.43275421 | E309: 4.9417868 | F309: 7.7409828e-07 | G309: 0.0001544846 | H309: - | J309: -
A310: TRINITY_DN204345_c1_g3 | B310: 178.38309 | C310: 2.0092063 | D310: 0.40718988 | E310: 4.9343227 | F310: 8.0429374e-07 | G310: 0.00015908597 | H310: - | I310: - | J310: -
A311: TRINITY_DN159737_c0_g1 | B311: 115.73399 | C311: 2.520542 | D311: 0.51191148 | E311: 4.9237849 | F311: 8.4886144e-07 | G311: 0.00016593752 | H311: - | I311: - | J311: -
A312: TRINITY_DN197353_c5_g6 | B312: 44.11581 | C312: 4.3144963 | D312: 0.87754938 | E312: 4.9165282 | F312: 8.809253e-07 | G312: 0.00017120425 | H312: K14554 | I312: - | J312: -
A313: TRINITY_DN211019_c4_g16 | B313: 89.75476 | C313: 2.3647647 | D313: 0.48178889 | E313: 4.9083005 | F313: 9.1869015e-07 | G313: 0.00017775817 | H313: - | I313: - | J313: -
A314: TRINITY_DN204380_c1_g1 | B314: 66.978882 | C314: 3.427965 | D314: 0.70084118 | E314: 4.8912152 | F314: 1.002153e-06 | G314: 0.00019088017 | H314: K06568 | I314: coreceptor activity involved in Wnt signaling pathway, planar cell polarity pathway | J314: -
A315: TRINITY_DN194275_c1_g1 | B315: 66.82365 | C315: 2.8099804 | D315: 0.57712256 | E315: 4.8689492 | F315: 1.1219323e-06 | G315: 0.00021010303 | H315: - | I315: - | J315: -
A316: TRINITY_DN203289_c5_g2 | B316: 257.63102 | C316: 2.4617103 | D316: 0.50689448 | E316: 4.8564552 | F316: 1.1950582e-06 | G316: 0.00022193227 | H316: - | I316: - | J316: -
A317: TRINITY_DN188500_c0_g1 | B317: 212.69656 | C317: 7.1799668 | D317: 1.4790523 | E317: 4.8544375 | F317: 1.2072894e-06 | G317: 0.000222965 | H317: K07424 | I317: heme binding | J317: GO:0001101,GO:0001516,GO:0001676,GO:0003008,GO:0003013,GO:0003018,GO:0003674,GO:0003824,GO:0004796,GO:0005575,GO:0005622,GO:0005623,GO:0005737,GO:0005783,GO:0005789,GO:0006082,GO:0006629,GO:0006631,GO:0006633,GO:0006636,GO:0006690,GO:0006692,GO:0006693,GO:0006873,GO:0008015,GO:0008150,GO:0008152,GO:0008610,GO:0009058,GO:0009636,GO:0009987,GO:0010033,GO:0012505,GO:0016020,GO:0016053,GO:0016491,GO:0016627,GO:0016628,GO:0016853,GO:0016860,GO:0019229,GO:0019369,GO:0019371,GO:0019725,GO:0019752,GO:0030002,GO:0030320,GO:0030644,GO:0031984,GO:0032501,GO:0032787,GO:0033559,GO:0033993,GO:0035150,GO:0035296,GO:0036134,GO:0042175,GO:0042221,GO:0042493,GO:0042592,GO:0043226,GO:0043227,GO:0043229,GO:0043231,GO:0043436,GO:0044057,GO:0044237,GO:0044238,GO:0044249,GO:0044255,GO:0044281,GO:0044283,GO:0044422,GO:0044424,GO:0044425,GO:0044432,GO:0044444,GO:0044446,GO:0044464,GO:0045471,GO:0045907,GO:0046394,GO:0046456,GO:0046457,GO:0046677,GO:0048518,GO:0048878,GO:0050789,GO:0050801,GO:0050880,GO:0050896,GO:0051239,GO:0051240,GO:0055064,GO:0055081,GO:0055082,GO:0055083,GO:0055114,GO:0065007,GO:0065008,GO:0070542,GO:0071704,GO:0072330,GO:0090066,GO:0097305,GO:0097746,GO:0098771,GO:0098827,GO:1901568,GO:1901570,GO:1901576,GO:1901700,GO:1903522,GO:1903524
A318: TRINITY_DN209774_c3_g1 | B318: 117.827 | C318: 2.3663113 | D318: 0.48887003 | E318: 4.840369 | F318: 1.2959829e-06 | G318: 0.00023803004 | H318: - | I318: - | J318: -
A319: TRINITY_DN196311_c0_g1 | B319: 25.550702 | C319: 7.7775301 | D319: 1.6094035 | E319: 4.8325545 | F319: 1.3479221e-06 | G319: 0.00024689131 | H319: - | I319: - | J319: -
A320: TRINITY_DN204930_c0_g1 | B320: 86.625461 | C320: 2.7094502 | D320: 0.56077264 | E320: 4.8316377 | F320: 1.3541453e-06 | G320: 0.00024735351 | H320: - | I320: - | J320: -
A321: TRINITY_DN179904_c1_g2 | B321: 50.287572 | C321: 3.0411576 | D321: 0.63082024 | E321: 4.8209576 | F321: 1.4287075e-06 | G321: 0.0002588516 | H321: K03158 | I321: - | J321: -
... A331: TRINITY_DN185508_c0_g1 | B331: 96.805792 | C331: 2.2630193 | D331: 0.47556351 | E331: 4.7586058 | F331: 1.9493475e-06 | G331: 0.00033416315 | H331: - | I331: - | J331: -
A332: TRINITY_DN142845_c0_g1 | B332: 40.577191 | C332: 3.9237159 | D332: 0.82571865 | E332: 4.7518799 | F332: 2.0153407e-06 | G332: 0.00034459233 | H332: - | J332: -
A333: TRINITY_DN216904_c2_g1 | B333: 42.043358 | C333: 3.6248249 | D333: 0.76296023 | E333: 4.751001 | F333: 2.024121e-06 | G333: 0.00034521074 | H333: - | I333: - | J333: -
A334: TRINITY_DN197755_c2_g10 | B334: 391.69992 | C334: 2.1964836 | D334: 0.46254606 | E334: 4.7486807 | F334: 2.0474786e-06 | G334: 0.00034830581 | H334: - | I334: iron assimilation by reduction and transport | J334: -
A335: TRINITY_DN167197_c0_g3 | B335: 29.059943 | C335: 4.4634341 | D335: 0.94153889 | E335: 4.7405733 | F335: 2.1311436e-06 | G335: 0.00036070279 | H335: - | I335: - | J335: -
A336: TRINITY_DN214928_c0_g5 | B336: 89.752491 | C336: 2.8326877 | D336: 0.59776263 | E336: 4.738817 | F336: 2.1496949e-06 | G336: 0.00036292386 | H336: - | I336: - | J336: -
A337: TRINITY_DN172750_c0_g2 | B337: 37.540306 | C337: 5.5194685 | D337: 1.1650058 | E337: 4.7377178 | F337: 2.161385e-06 | G337: 0.0003633152 | H337: - | I337: - | J337: -
A338: TRINITY_DN147572_c0_g1 | B338: 32.90054 | C338: 4.0582497 | D338: 0.86486006 | E338: 4.6923773 | F338: 2.7004848e-06 | G338: 0.00044016306 | H338: - | I338: - | J338: -
A339: TRINITY_DN209823_c0_g5 | B339: 40.70014 | C339: 3.4677498 | D339: 0.73908295 | E339: 4.691963 | F339: 2.7059609e-06 | G339: 0.00044016306 | H339: - | J339: -
A340: TRINITY_DN209252_c0_g3 | B340: 758.12345 | C340: 4.4122216 | D340: 0.9410473 | E340: 4.6886289 | F340: 2.7504164e-06 | G340: 0.00044578263 | H340: - | I340: - | J340: -
A341: TRINITY_DN118766_c0_g2 | B341: 43.943346 | C341: 4.1731897 | D341: 0.89050082 | E341: 4.6863402 | F341: 2.7813384e-06 | G341: 0.00044761362 | H341: K06568 | I341: - | J341: -
A342: TRINITY_DN206287_c2_g1 | B342: 163.05516 | C342: 2.0686916 | D342: 0.44214955 | E342: 4.6787147 | F342: 2.8867873e-06 | G342: 0.00045951468 | H342: K09310 | I342: - | J342: -
...

Sheet TableS2
A1: Table S2 | Heat treatment DEGs in Orbicella faveolata host -2>logFC>2 padj<0.01. p value is obtained from a Wald test, and BH adjusted p-values are provided as padj (DESeq2).
A2: id | B2: baseMean | C2: log2FoldChange | D2: lfcSE | E2: stat | F2: pvalue | G2: padj | H2: KO | I2: Description | J2: GO
A3: TRINITY_DN332658_c0_g1 | B3: 853.28024 | C3: -7.8160198 | D3: 0.44626899 | E3: -17.514145 | F3: 1.1175236e-68 | G3: 7.4712041e-64 | H3: - | I3: - | J3: -
A4: TRINITY_DN219930_c3_g12 | B4: 17189.452 | C4: -6.1423206 | D4: 0.41410311 | E4: -14.832829 | F4: 8.9864517e-50 | G4: 3.0039462e-45 | H4: - | I4: - | J4: -
A5: TRINITY_DN134730_c0_g1 | B5: 724.80479 | C5: -6.3391752 | D5: 0.43166796 | E5: -14.685304 | F5: 8.0074254e-49 | G5: 1.7844547e-44 | H5: - | I5: - | J5: -
A6: TRINITY_DN213821_c5_g11 | B6: 652.7618 | C6: -6.1424334 | D6: 0.42530586 | E6: -14.442391 | F6: 2.7995999e-47 | G6: 4.6791813e-43 | H6: - | I6: - | J6: -
A7: TRINITY_DN82298_c0_g2 | B7: 488.75958 | C7: -8.0228644 | D7: 0.56707542 | E7: -14.147791 | F7: 1.9271676e-45 | G7: 2.5768158e-41 | H7: - | I7: - | J7: -
A8: TRINITY_DN206197_c3_g9 | B8: 564.31166 | C8: -4.7257318 | D8: 0.3800276 | E8: -12.435233 | F8: 1.6824885e-35 | G8: 1.8747128e-31 | H8: - | I8: - | J8: -
A9: TRINITY_DN146551_c0_g1 | B9: 243.19211 | C9: -6.6302432 | D9: 0.55856638 | E9: -11.870108 | F9: 1.6924933e-32 | G9: 1.616452e-28 | H9: - | I9: - | J9: -
A10: TRINITY_DN204832_c1_g3 | B10: 443.8292 | C10: -4.9017353 | D10: 0.41483347 | E10: -11.816152 | F10: 3.2210352e-32 | G10: 2.6917789e-28 | H10: - | I10: - | J10: -
A11: TRINITY_DN134730_c0_g2 | B11: 280.06927 | C11: -5.048294 | D11: 0.44241059 | E11: -11.41088 | F11: 3.6897913e-30 | G11: 2.7408999e-26 | H11: - | I11: - | J11: -
A12: TRINITY_DN136985_c0_g4 | B12: 167.13953 | C12: -6.5847474 | D12: 0.62659617 | E12: -10.508758 | F12: 7.8723586e-26 | G12: 5.2630654e-22 | H12: - | I12: - | J12: -
A13: TRINITY_DN202268_c1_g1 | B13: 286.18119 | C13: -5.34492 | D13: 0.51404622 | E13: -10.397742 | F13: 2.538775e-25 | G13: 1.5429982e-21 | H13: - | I13: - | J13: -
A14: TRINITY_DN216688_c3_g3 | B14: 259.56683 | C14: -5.2253503 | D14: 0.50865607 | E14: -10.272855 | F14: 9.3398538e-25 | G14: 4.8031994e-21 | H14: K19501 | I14: anoctamin-7 | J14: -
... A280: TRINITY_DN209765_c1_g1 | B280: 274.83066 | C280: 3.0812941 | D280: 0.48124885 | E280: 6.4027045 | F280: 1.5264849e-10 | G280: 1.0742437e-07 | H280: - | I280: - | J280: -
A281: TRINITY_DN216535_c1_g1 | B281: 370.76929 | C281: 2.5462334 | D281: 0.3979635 | E281: 6.3981582 | F281: 1.5726235e-10 | G281: 1.0951848e-07 | H281: 0 | I281: Mab-21 | J281: 0
A282: TRINITY_DN157508_c1_g1 | B282: 93.221807 | C282: 3.2199267 | D282: 0.50477132 | E282: 6.3789812 | F282: 1.7826992e-10 | G282: 1.2161465e-07 | H282: - | I282: - | J282: -
A283: TRINITY_DN206242_c4_g4 | B283: 90.686728 | C283: 3.676883 | D283: 0.57713154 | E283: 6.3709619 | F283: 1.8784629e-10 | G283: 1.2685317e-07 | H283: - | I283: - | J283: -
A284: TRINITY_DN221098_c7_g5 | B284: 142.24057 | C284: 2.6584246 | D284: 0.42590608 | E284: 6.2418095 | F284: 4.3253769e-10 | G284: 2.6529639e-07 | H284: - | I284: - | J284: -
A285: TRINITY_DN217206_c0_g25 | B285: 364.83858 | C285: 2.8006016 | D285: 0.45023136 | E285: 6.220361 | F285: 4.9601246e-10 | G285: 3.0146284e-07 | H285: K02583 | I285: tumor necrosis factor receptor superfamily member 16 | J285: -
A286: TRINITY_DN185682_c0_g1 | B286: 266.68237 | C286: 3.0667185 | D286: 0.49424244 | E286: 6.2048871 | F286: 5.47362e-10 | G286: 3.2673113e-07 | H286: - | I286: - | J286: -
A287: TRINITY_DN221118_c1_g1 | B287: 240.57226 | C287: 3.268584 | D287: 0.52940968 | E287: 6.1740163 | F287: 6.6576657e-10 | G287: 3.9389225e-07 | H287: K06767 | I287: Immunoglobulin C-2 Type | J287: GO:0000902,GO:0003674,GO:0005488,GO:0005515,GO:0005575,GO:0005623,GO:0005886,GO:0005887,GO:0007155,GO:0007156,GO:0007275,GO:0007399,GO:0008150,GO:0009653,GO:0009987,GO:0016020,GO:0016021,GO:0016043,GO:0022008,GO:0022610,GO:0030030,GO:0030154,GO:0030182,GO:0031175,GO:0031224,GO:0031226,GO:0032501,GO:0032502,GO:0032989,GO:0032990,GO:0042802,GO:0044425,GO:0044459,GO:0044464,GO:0048468,GO:0048666,GO:0048699,GO:0048731,GO:0048812,GO:0048856,GO:0048858,GO:0048869,GO:0071840,GO:0071944,GO:0098609,GO:0098742,GO:0120036,GO:0120039
A288: TRINITY_DN220650_c4_g1 | B288: 1073.4354 | C288: 2.7054007 | D288: 0.43890495 | E288: 6.1639785 | F288: 7.0939599e-10 | G288: 4.1491163e-07 | H288: - | I288: - | J288: -
A289: TRINITY_DN55293_c0_g1 | B289: 62.278644 | C289: 4.2407688 | D289: 0.68809918 | E289: 6.1630197 | F289: 7.1370633e-10 | G289: 4.1491163e-07 | H289: - | I289: - | J289: -
A290: TRINITY_DN187917_c6_g5 | B290: 206.18279 | C290: 2.5611199 | D290: 0.41646881 | E290: 6.1496078 | F290: 7.7674796e-10 | G290: 4.4734331e-07 | H290: - | I290: - | J290: -
A291: TRINITY_DN176584_c0_g1 | B291: 260.97765 | C291: 2.9296428 | D291: 0.4774014 | E291: 6.1366448 | F291: 8.4282521e-10 | G291: 4.7751762e-07 | H291: - | I291: Collagen triple helix | J291: -
A292: TRINITY_DN218256_c2_g2 | B292: 186.71199 | C292: 2.4612949 | D292: 0.40148702 | E292: 6.1304471 | F292: 8.7632472e-10 | G292: 4.9232512e-07 | H292: K02583 | I292: Tumor necrosis factor receptor / nerve growth factor receptor repeats. | J292: -
A293: TRINITY_DN206836_c2_g5 | B293: 227.47214 | C293: 2.3554856 | D293: 0.3845191 | E293: 6.1257961 | F293: 9.0231284e-10 | G293: 5.0270104e-07 | H293: K21077 | I293: - | J293: -
... A341: TRINITY_DN196159_c0_g1 | B341: 78.842529 | C341: 2.8340587 | D341: 0.53131091 | E341: 5.3340871 | F341: 9.6026418e-08 | G341: 2.652829e-05 | H341: K05142 | I341: - | J341: -
A342: TRINITY_DN215853_c0_g4 | B342: 61.398783 | C342: 3.2208602 | D342: 0.60708144 | E342: 5.3054829 | F342: 1.1237511e-07 | G342: 3.02937e-05 | H342: K02583 | I342: Tumor necrosis factor receptor / nerve growth factor receptor repeats. | J342: 0
A343: TRINITY_DN175729_c0_g2 | B343: 102.01682 | C343: 2.8599802 | D343: 0.5395029 | E343: 5.3011397 | F343: 1.1508199e-07 | G343: 3.0775226e-05 | H343: - | I343: - | J343: -
A344: TRINITY_DN212486_c0_g8 | B344: 104.61112 | C344: 2.47389 | D344: 0.46783371 | E344: 5.2879686 | F344: 1.2368223e-07 | G344: 3.2554233e-05 | H344: - | I344: - | J344: -
A345: TRINITY_DN199955_c1_g1 | B345: 206.27998 | C345: 2.6815133 | D345: 0.50718215 | E345: 5.2870814 | F345: 1.2428335e-07 | G345: 3.2584171e-05 | H345: K06550,K06756,K06757,K06760 | I345: Cell adhesion molecule | J345: GO:0000003,GO:0000132,GO:0000226,GO:0000278,GO:0000902,GO:0000904,GO:0001101,GO:0001501,GO:0001558,GO:0001667,GO:0001932,GO:0002009,GO:0002064,GO:0002165,GO:0002252,GO:0002376,GO:0003007,GO:0003381,GO:0003382,GO:0003383,GO:0003384,GO:0003674,GO:0004888,GO:0005102,GO:0005178,GO:0005488,GO:0005509,GO:0005515,GO:0005575,GO:0005622,GO:0005623,GO:0005737,GO:0005768,GO:0005886,GO:0005887,GO:0005911,GO:0005912,GO:0005913,GO:0005918,GO:0005919,GO:0006582,GO:0006725,GO:0006928,GO:0006935,GO:0006950,GO:0006952,GO:0006955,GO:0006996,GO:0007010,GO:0007017,GO:0007043,GO:0007049,GO:0007154,GO:0007155,GO:0007156,GO:0007157,GO:0007158,GO:0007159,GO:0007160,GO:0007163,GO:0007165,GO:0007166,GO:0007167,GO:0007169,GO:0007173,GO:0007272,GO:0007275,GO:0007369,GO:0007399,GO:0007409,GO:0007411,GO:0007413,GO:0007417,GO:0007420,GO:0007424,GO:0007444,GO:0007507,GO:0007552,GO:0007560,GO:0007610,GO:0007617,GO:0007618,GO:0007619,GO:0008037,GO:0008038,GO:0008045,GO:0008049,GO:0008050,GO:0008092,GO:0008150,GO:0008152,GO:0008361,GO:0008366,GO:0009410,GO:0009605,GO:0009611,GO:0009636,GO:0009653,GO:0009719,GO:0009725,GO:0009790,GO:0009791,GO:0009792,GO:0009886,GO:0009887,GO:0009888,GO:0009893,GO:0009897,GO:0009966,GO:0009967,GO:0009986,GO:0009987,GO:0010001,GO:0010033,GO:0010243,GO:0010468,GO:0010604,GO:0010628,GO:0010646,GO:0010647,GO:0010720,GO:0010769,GO:0010770,GO:0010810,GO:0010811,GO:0010975,GO:0010976,GO:0012505,GO:0014070,GO:0014823,GO:0016020,GO:0016021,GO:0016043,GO:0016049,GO:0016319,GO:0016328,GO:0016358,GO:0016477,GO:0017154,GO:0018958,GO:0019098,GO:0019220,GO:0019222,GO:0019748,GO:0019904,GO:0019953,GO:0019991,GO:0021675,GO:0021682,GO:0021700,GO:0021782,GO:0022008,GO:0022402,GO:0022407,GO:0022409,GO:0022414,GO:0022603,GO:0022604,GO:0022607,GO:0022610,GO:0023051,GO:0023052,GO:0023056,GO:0030010,GO:0030016,GO:0030017,GO:0030029,GO:0030030,GO:0030048,GO:0030054,GO:0030154,GO:0030155,GO:0030165,GO:0030175,GO:0030182,GO:0030307,GO:0030424,GO:0030425,GO:0030426,GO:0030427,GO:0030506,GO:0030516,GO:0030673,GO:0030855,GO:0031099,GO:0031102,GO:0031103,GO:0031175,GO:0031224,GO:0031226,GO:0031252,GO:0031253,GO:0031256,GO:0031323,GO:0031344,GO:0031346,GO:0031399,GO:0031406,GO:0031410,GO:0031589,GO:0031960,GO:0031982,GO:0032101,GO:0032268,GO:0032501,GO:0032502,GO:0032504,GO:0032535,GO:0032589,GO:0032590,GO:0032809,GO:0032870,GO:0032879,GO:0032989,GO:0032990,GO:0033267,GO:0033554,GO:0033563,GO:0033564,GO:0033627,GO:0033631,GO:0033691,GO:0033993,GO:0034109,GO:0034329,GO:0034330,GO:0035006,GO:0035010,GO:0035011,GO:0035150,GO:0035151,GO:0035152,GO:0035239,GO:0035295,GO:0035690,GO:0036094,GO:0036477,GO:0038023,GO:0038127,GO:0040001,GO:0040007,GO:0040008,GO:0040011,GO:0040012,GO:0042063,GO:0042074,GO:0042221,GO:0042325,GO:0042330,GO:0042440,GO:0042493,GO:0042734,GO:0042802,GO:0042995,GO:0043005,GO:0043025,GO:0043167,GO:0043168,GO:0043169,GO:0043177,GO:0043195,GO:0043200,GO:0043226,GO:0043227,GO:0043228,GO:0043229,GO:0043232,GO:0043292,GO:0043296,GO:0043297,GO:0043408,GO:0043621,GO:0043679,GO:0044085,GO:0044237,GO:0044292,GO:0044294,GO:0044295,GO:0044297,GO:0044298,GO:0044304,GO:0044306,GO:0044422,GO:0044424,GO:0044425,GO:0044444,GO:0044449,GO:0044456,GO:0044459,GO:0044463,GO:0044464,GO:0044703,GO:0044877,GO:0045087,GO:0045121,GO:0045202,GO:0045216,GO:0045471,GO:0045595,GO:0045597,GO:0045664,GO:0045666,GO:0045773,GO:0045785,GO:0045924,GO:0045927,GO:0046677,GO:0046872,GO:0048036,GO:0048468,GO:0048513,GO:0048518,GO:0048522,GO:0048545,GO:0048563,GO:0048569,GO:0048583,GO:0048584,GO:0048588,GO:0048589,GO:0048598,GO:0048609,GO:0048638,GO:0048639,GO:0048666,GO:0048667,GO:0048675,GO:0048678,GO:0048699,GO:0048707,GO:0048729,GO:0048731,GO:0048812,GO:0048813,GO:0048814,GO:0048856,GO:0048858,GO:0048869,GO:0048870,GO:0050767,GO:0050769,GO:0050770,GO:0050772,GO:0050773,GO:0050775,GO:0050789,GO:0050793,GO:0050794,GO:0050808,GO:0050839,GO:0050848,GO:0050850,GO:0050896,GO:0050900,GO:0050920,GO:0051094,GO:0051128,GO:0051130,GO:0051171,GO:0051174,GO:0051179,GO:0051216,GO:0051234,GO:0051239,GO:0051240,GO:0051246,GO:0051270,GO:0051293,GO:0051294,GO:0051384,GO:0051640,GO:0051641,GO:0051649,GO:0051653,GO:0051656,GO:0051674,GO:0051704,GO:0051716,GO:0051960,GO:0051962,GO:0060089,GO:0060179,GO:0060180,GO:0060255,GO:0060284,GO:0060322,GO:0060429,GO:0060536,GO:0060541,GO:0060560,GO:0060562,GO:0060856,GO:0060857,GO:0061343,GO:0061387,GO:0061448,GO:0061564,GO:0065007,GO:0065008,GO:0070160,GO:0070161,GO:0070252,GO:0070372,GO:0070593,GO:0070848,GO:0070887,GO:0071229,GO:0071230,GO:0071236,GO:0071310,GO:0071361,GO:0071363,GO:0071383,GO:0071384,GO:0071385,GO:0071396,GO:0071407,GO:0071417,GO:0071466,GO:0071495,GO:0071526,GO:0071542,GO:0071548,GO:0071549,GO:0071559,GO:0071560,GO:0071695,GO:0071704,GO:0071840,GO:0071944,GO:0072359,GO:0072499,GO:0080090,GO:0090066,GO:0097060,GO:0097066,GO:0097067,GO:0097068,GO:0097069,GO:0097237,GO:0097305,GO:0097306,GO:0097327,GO:0097367,GO:0097447,GO:0097458,GO:0097485,GO:0097708,GO:0098552,GO:0098589,GO:0098590,GO:0098609,GO:0098742,GO:0098793,GO:0098805,GO:0098857,GO:0098858,GO:0099080,GO:0099081,GO:0099512,GO:0106030,GO:0120025,GO:0120035,GO:0120036,GO:0120038,GO:0120039,GO:0150034,GO:1900006,GO:1901360,GO:1901615,GO:1901654,GO:1901655,GO:1901698,GO:1901699,GO:1901700,GO:1901701,GO:1902531,GO:1902533,GO:1902667,GO:1902850,GO:1903047,GO:1903859,GO:1904386,GO:1904387,GO:1990089,GO:1990090,GO:1990138,GO:2000026
A346: TRINITY_DN207874_c0_g5 | B346: 90.779499 | C346: 2.6663614 | D346: 0.50509259 | E346: 5.2789558 | F346: 1.2992214e-07 | G346: 3.3536465e-05 | H346: - | I346: - | J346: -
A347: TRINITY_DN186268_c0_g2 | B347: 145.22284 | C347: 2.2115662 | D347: 0.42065425 | E347: 5.257444 | F347: 1.4607136e-07 | G347: 3.6851323e-05 | H347: - | I347: - | J347: -
A348: TRINITY_DN177596_c1_g2 | B348: 67.814579 | C348: 2.951142 | D348: 0.56249703 | E348: 5.2465024 | F348: 1.550138e-07 | G348: 3.881441e-05 | H348: K03158 | I348: - | J348: -
A349: TRINITY_DN213457_c1_g6 | B349: 359.12489 | C349: 2.5799913 | D349: 0.49267919 | E349: 5.2366557 | F349: 1.6351235e-07 | G349: 4.0702683e-05 | H349: K13912 | I349: - | J349: -
A350: TRINITY_DN463772_c0_g1 | B350: 86.814168 | C350: 3.2286445 | D350: 0.61661807 | E350: 5.2360523 | F350: 1.6404745e-07 | G350: 4.0702683e-05 | H350: - | I350: - | J350: -
A351: TRINITY_DN191087_c2_g2 | B351: 76.828511 | C351: 2.9821722 | D351: 0.56958678 | E351: 5.2356767 | F351: 1.6438149e-07 | G351: 4.0702683e-05 | H351: - | I351: - | J351: -
A352: TRINITY_DN219460_c3_g3 | B352: 146.92741 | C352: 2.146964 | D352: 0.41272626 | E352: 5.2019079 | F352: 1.9725297e-07 | G352: 4.7780244e-05 | H352: - | I352: - | J352: -
...

Sheet TableS3
A1: Table S3 | Heat treatment DEGs in Orbicella faveolata Symbiodinium A3 -2>logFC>2 padj<0.001. p value is obtained from a Wald test, and BH adjusted p-values are provided as padj (DESeq2).
A2: id | B2: baseMean | C2: log2FoldChange | D2: lfcSE | E2: stat | F2: pvalue | G2: padj | H2: KO | I2: Description | J2: GO
A3: TRINITY_DN69788_c0_g2 | B3: 146.24651 | C3: -10.470373 | D3: 1.650585 | E3: -6.3434315 | F3: 2.2470287e-10 | G3: 3.5571713e-07 | H3: - | I3: - | J3: =VLOOKUP(A3,TableS4!A:J,10,FALSE) -> -
A4: TRINITY_DN19131_c0_g1 | B4: 125.82011 | C4: -10.252471 | D4: 1.9069713 | E4: -5.376311 | F4: 7.6027427e-08 | G4: 4.2420683e-05 | H4: - | I4: RNA-binding protein mei2 homologue | J4: =VLOOKUP(A4,TableS4!A:J,10,FALSE) -> -
A5: TRINITY_DN48606_c0_g1 | B5: 26.95193 | C5: -8.0330009 | D5: 1.5328869 | E5: -5.2404393 | F5: 1.6019478e-07 | G5: 7.4223579e-05 | H5: K01070,K09795 | I5: yeiG, Serine hydrolase involved in the detoxification of formaldehyde | J5: =VLOOKUP(A5,TableS4!A:J,10,FALSE) -> -
A6: TRINITY_DN29380_c0_g1 | B6: 26.953588 | C6: -8.0209479 | D6: 1.5334177 | E6: -5.2307653 | F6: 1.6880975e-07 | G6: 7.7584416e-05 | H6: - | I6: - | J6: =VLOOKUP(A6,TableS4!A:J,10,FALSE) -> -
A7: TRINITY_DN68465_c0_g1 | B7: 24.203106 | C7: -7.890102 | D7: 1.5552742 | E7: -5.0731259 | F7: 3.9133344e-07 | G7: 0.00015595869 | H7: - | I7: - | J7: =VLOOKUP(A7,TableS4!A:J,10,FALSE) -> -
A8: TRINITY_DN54874_c0_g2 | B8: 24.308711 | C8: -7.8828991 | D8: 1.5431775 | E8: -5.1082257 | F8: 3.2519814e-07 | G8: 0.00013627237 | H8: - | I8: - | J8: =VLOOKUP(A8,TableS4!A:J,10,FALSE) -> -
A9: TRINITY_DN6716_c0_g1 | B9: 23.892919 | C9: -7.8666177 | D9: 1.5502967 | E9: -5.0742658 | F9: 3.889949e-07 | G9: 0.00015595869 | H9: K06641 | I9: DUN1, Belongs to the protein kinase superfamily | J9: =VLOOKUP(A9,TableS4!A:J,10,FALSE) -> GO:0000075,GO:0000077,GO:0003674,GO:0003824,GO:0004672,GO:0004674,GO:0004683,GO:0005488,GO:0005515,GO:0005516,GO:0005575,GO:0005622,GO:0005623,GO:0005634,GO:0006139,GO:0006259,GO:0006260,GO:0006261,GO:0006275,GO:0006464,GO:0006468,GO:0006725,GO:0006793,GO:0006796,GO:0006807,GO:0006950,GO:0006974,GO:0006979,GO:0007154,GO:0007165,GO:0008150,GO:0008152,GO:0008156,GO:0009058,GO:0009059,GO:0009889,GO:0009890,GO:0009892,GO:0009987,GO:0010556,GO:0010558,GO:0010605,GO:0016301,GO:0016310,GO:0016740,GO:0016772,GO:0016773,GO:0018105,GO:0018107,GO:0018193,GO:0018209,GO:0018210,GO:0019219,GO:0019222,GO:0019538,GO:0023052,GO:0031323,GO:0031324,GO:0031326,GO:0031327,GO:0031570,GO:0033554,GO:0034599,GO:0034641,GO:0034645,GO:0035556,GO:0036211,GO:0042221,GO:0043170,GO:0043226,GO:0043227,GO:0043229,GO:0043231,GO:0043412,GO:0044237,GO:0044238,GO:0044249,GO:0044260,GO:0044267,GO:0044424,GO:0044464,GO:0045005,GO:0045786,GO:0045934,GO:0046483,GO:0048478,GO:0048519,GO:0048523,GO:0050789,GO:0050794,GO:0050896,GO:0051052,GO:0051053,GO:0051171,GO:0051172,GO:0051716,GO:0051726,GO:0060255,GO:0065007,GO:0070887,GO:0071704,GO:0080090,GO:0090304,GO:0090329,GO:0140096,GO:1901360,GO:1901564,GO:1901576,GO:2000104,GO:2000112,GO:2000113
A10: TRINITY_DN7731_c0_g2 | B10: 22.987931 | C10: -7.794574 | D10: 1.5494175 | E10: -5.030648 | F10: 4.8882494e-07 | G10: 0.00017972989 | H10: - | I10: - | J10: =VLOOKUP(A10,TableS4!A:J,10,FALSE) -> -
A11: TRINITY_DN135274_c0_g1 | B11: 22.340327 | C11: -7.7507057 | D11: 1.5537625 | E11: -4.9883464 | F11: 6.0898287e-07 | G11: 0.00021827631 | H11: - | I11: - | J11: =VLOOKUP(A11,TableS4!A:J,10,FALSE) -> -
A12: TRINITY_DN70100_c0_g3 | B12: 21.300845 | C12: -7.7054465 | D12: 1.5704643 | E12: -4.9064768 | F12: 9.2726944e-07 | G12: 0.00030903559 | H12: K21989 | I12: ERD4, CSC1-like protein ERD4 | J12: =VLOOKUP(A12,TableS4!A:J,10,FALSE) -> GO:0005575,GO:0005622,GO:0005623,GO:0005737,GO:0005773,GO:0005774,GO:0005886,GO:0005911,GO:0009506,GO:0009507,GO:0009526,GO:0009536,GO:0009941,GO:0016020,GO:0030054,GO:0031090,GO:0031967,GO:0031975,GO:0043226,GO:0043227,GO:0043229,GO:0043231,GO:0044422,GO:0044424,GO:0044434,GO:0044435,GO:0044437,GO:0044444,GO:0044446,GO:0044464,GO:0055044,GO:0071944,GO:0098588,GO:0098805
A13: TRINITY_DN62247_c0_g2 | B13: 19.66822 | C13: -7.5908275 | D13: 1.5826802 | E13: -4.7961851 | F13: 1.6171584e-06 | G13: 0.00048252281 | H13: - | I13: - | J13: =VLOOKUP(A13,TableS4!A:J,10,FALSE) -> -
A14: TRINITY_DN72903_c0_g2 | B14: 19.593159 | C14: -7.5613629 | D14: 1.5716821 | E14: -4.8110001 | F14: 1.5017694e-06 | G14: 0.0004601389 | H14: - | I14: - | J14: =VLOOKUP(A14,TableS4!A:J,10,FALSE) -> -
A15: TRINITY_DN222617_c0_g2 | B15: 18.396927 | C15: -7.5032421 | D15: 1.6212795 | E15: -4.6279756 | F15: 3.6925743e-06 | G15: 0.00091895114 | I15: protein polyglycylation | J15: =VLOOKUP(A15,TableS4!A:J,10,FALSE) -> -
A16: TRINITY_DN154524_c0_g3 | B16: 17.64869 | C16: -7.4181116 | D16: 1.5872498 | E16: -4.6735626 | F16: 2.9601935e-06 | G16: 0.00075650865 | H16: - | I16: - | J16: =VLOOKUP(A16,TableS4!A:J,10,FALSE) -> -
A17: TRINITY_DN138993_c0_g1 | B17: 17.183409 | C17: -7.3668378 | D17: 1.5966879 | E17: -4.6138247 | F17: 3.9532596e-06 | G17: 0.00097110458 | H17: - | I17: - | J17: =VLOOKUP(A17,TableS4!A:J,10,FALSE) -> -
A18: TRINITY_DN107864_c0_g2 | B18: 93.407768 | C18: -6.764265 | D18: 0.89161606 | E18: -7.5865222 | F18: 3.2860612e-14 | G18: 1.3376616e-10 | H18: - | I18: - | J18: =VLOOKUP(A18,TableS4!A:J,10,FALSE) -> -
A19: TRINITY_DN141779_c0_g5 | B19: 34.69274 | C19: -5.9432244 | D19: 1.1199064 | E19: -5.3068941 | F19: 1.1150891e-07 | G19: 5.8301769e-05 | H19: - | I19: - | J19: =VLOOKUP(A19,TableS4!A:J,10,FALSE) -> -
A20: TRINITY_DN72876_c0_g1 | B20: 24.885835 | C20: -4.3931639 | D20: 0.92089393 | E20: -4.7705428 | F20: 1.8373017e-06 | G20: 0.0005315118 | H20: - | I20: - | J20: =VLOOKUP(A20,TableS4!A:J,10,FALSE) -> -
A21: TRINITY_DN389124_c0_g1 | B21: 65.5002 | C21: -3.7640988 | D21: 0.48227977 | E21: -7.8048035 | F21: 5.9594348e-15 | G21: 3.4876628e-11 | H21: K03654,K07114,K14949 | I21: Vault protein inter-alpha-trypsin domain | J21: =VLOOKUP(A21,TableS4!A:J,10,FALSE) -> -
A22: TRINITY_DN198015_c0_g4 | B22: 33.226877 | C22: -3.1357024 | D22: 0.61249216 | E22: -5.1195796 | F22: 3.0621757e-07 | G22: 0.00013023388 | H22: - | I22: - | J22: =VLOOKUP(A22,TableS4!A:J,10,FALSE) -> -
A23: TRINITY_DN225772_c0_g1 | B23: 62.960565 | C23: -3.1256838 | D23: 0.52047759 | E23: -6.0054148 | F23: 1.9084332e-09 | G23: 1.9774838e-06 | H23: - | I23: - | J23: =VLOOKUP(A23,TableS4!A:J,10,FALSE) -> -
A24: TRINITY_DN100360_c0_g2 | B24: 32.350527 | C24: -2.9733215 | D24: 0.62704336 | E24: -4.7418116 | F24: 2.1181555e-06 | G24: 0.00059173374 | H24: - | I24: - | J24: =VLOOKUP(A24,TableS4!A:J,10,FALSE) -> -
A25: TRINITY_DN157834_c0_g3 | B25: 70.737752 | C25: -2.8462988 | D25: 0.40867229 | E25: -6.9647462 | F25: 3.2899642e-12 | G25: 8.9283363e-09 | H25: K19947 | I25: NADPH:sulfur oxidoreductase activity | J25: =VLOOKUP(A25,TableS4!A:J,10,FALSE) -> -
A26: TRINITY_DN122184_c0_g2 | B26: 58.617122 | C26: -2.8365078 | D26: 0.46035759 | E26: -6.1615314 | F26: 7.2044781e-10 | G26: 9.3314365e-07 | H26: - | I26: - | J26: =VLOOKUP(A26,TableS4!A:J,10,FALSE) -> -
A27: TRINITY_DN187798_c1_g1 | B27: 41.209388 | C27: -2.6863578 | D27: 0.57002662 | E27: -4.7126882 | F27: 2.4447006e-06 | G27: 0.00066344517 | I27: Protein tyrosine kinase | J27: =VLOOKUP(A27,TableS4!A:J,10,FALSE) -> -
A28: TRINITY_DN430167_c0_g1 | B28: 71.384812 | C28: -2.6797981 | D28: 0.41695692 | E28: -6.4270383 | F28: 1.3011404e-10 | G28: 2.1809409e-07 | H28: - | I28: - | J28: =VLOOKUP(A28,TableS4!A:J,10,FALSE) -> -
A29: TRINITY_DN128742_c0_g3 | B29: 43.364248 | C29: -2.6703418 | D29: 0.49714702 | E29: -5.3713322 | F29: 7.8157076e-08 | G29: 4.2420683e-05 | H29: - | I29: - | J29: =VLOOKUP(A29,TableS4!A:J,10,FALSE) -> -
A30: TRINITY_DN310617_c0_g1 | B30: 127.31892 | C30: -2.6466205 | D30: 0.3157197 | E30: -8.3828171 | F30: 5.1675724e-17 | G30: 4.9083325e-13 | H30: K07238 | I30: ZIP family transporter | J30: =VLOOKUP(A30,TableS4!A:J,10,FALSE) -> -
A31: TRINITY_DN69828_c0_g1 | B31: 42.542187 | C31: -2.5762215 | D31: 0.50356781 | E31: -5.1159375 | F31: 3.1218636e-07 | G31: 0.00013178889 | H31: - | I31: - | J31: =VLOOKUP(A31,TableS4!A:J,10,FALSE) -> -
A32: TRINITY_DN157925_c0_g3 | B32: 76.905348 | C32: -2.5252777 | D32: 0.41837772 | E32: -6.0358801 | F32: 1.5809864e-09 | G32: 1.7666748e-06 | I32: Calcium-dependent protein kinase | J32: =VLOOKUP(A32,TableS4!A:J,10,FALSE) -> GO:0000165,GO:0000187,GO:0001817,GO:0001932,GO:0001934,GO:0002218,GO:0002221,GO:0002224,GO:0002237,GO:0002253,GO:0002376,GO:0002682,GO:0002684,GO:0002757,GO:0002758,GO:0002764,GO:0003674,GO:0003824,GO:0004672,GO:0004674,GO:0004683,GO:0005488,GO:0005515,GO:0005516,GO:0005575,GO:0005622,GO:0005623,GO:0005634,GO:0005654,GO:0005737,GO:0005813,GO:0005815,GO:0005829,GO:0005856,GO:0006082,GO:0006464,GO:0006468,GO:0006690,GO:0006691,GO:0006793,GO:0006796,GO:0006807,GO:0006810,GO:0006897,GO:0006907,GO:0006950,GO:0006952,GO:0006954,GO:0006974,GO:0007154,GO:0007165,GO:0007166,GO:0007167,GO:0007169,GO:0008150,GO:0008152,GO:0009605,GO:0009607,GO:0009617,GO:0009892,GO:0009893,GO:0009894,GO:0009895,GO:0009931,GO:0009966,GO:0009967,GO:0009987,GO:0010033,GO:0010468,GO:0010562,GO:0010604,GO:0010605,GO:0010608,GO:0010628,GO:0010646,GO:0010647,GO:0010857,GO:0015630,GO:0016192,GO:0016301,GO:0016310,GO:0016740,GO:0016772,GO:0016773,GO:0018105,GO:0018193,GO:0018209,GO:0019219,GO:0019220,GO:0019222,GO:0019538,GO:0019752,GO:0019899,GO:0019900,GO:0019901,GO:0023014,GO:0023051,GO:0023052,GO:0023056,GO:0031323,GO:0031324,GO:0031325,GO:0031329,GO:0031330,GO:0031347,GO:0031349,GO:0031399,GO:0031401,GO:0031974,GO:0031981,GO:0032147,GO:0032268,GO:0032270,GO:0032496,GO:0032675,GO:0032680,GO:0033554,GO:0033674,GO:0033993,GO:0034097,GO:0035556,GO:0035924,GO:0036211,GO:0042221,GO:0042325,GO:0042327,GO:0043085,GO:0043170,GO:0043207,GO:0043226,GO:0043227,GO:0043228,GO:0043229,GO:0043231,GO:0043232,GO:0043233,GO:0043405,GO:0043406,GO:0043408,GO:0043410,GO:0043412,GO:0043436,GO:0043487,GO:0043488,GO:0043489,GO:0043549,GO:0044093,GO:0044237,GO:0044238,GO:0044260,GO:0044267,GO:0044281,GO:0044351,GO:0044422,GO:0044424,GO:0044428,GO:0044430,GO:0044444,GO:0044446,GO:0044464,GO:0045088,GO:0045089,GO:0045859,GO:0045860,GO:0045934,GO:0045937,GO:0046777,GO:0048010,GO:0048255,GO:0048518,GO:0048519,GO:0048522,GO:0048523,GO:0048583,GO:0048584,GO:0050776,GO:0050778,GO:0050789,GO:0050790,GO:0050794,GO:0050896,GO:0051019,GO:0051171,GO:0051172,GO:0051173,GO:0051174,GO:0051179,GO:0051234,GO:0051239,GO:0051246,GO:0051247,GO:0051252,GO:0051253,GO:0051338,GO:0051347,GO:0051704,GO:0051707,GO:0051716,GO:0060255,GO:0061013,GO:0065007,GO:0065008,GO:0065009,GO:0070013,GO:0070848,GO:0070887,GO:0070935,GO:0071310,GO:0071363,GO:0071704,GO:0071900,GO:0071902,GO:0080090,GO:0080134,GO:0080135,GO:0098657,GO:0140096,GO:1900034,GO:1901564,GO:1901568,GO:1901700,GO:1902369,GO:1902373,GO:1902531,GO:1902533,GO:1903311,GO:1903312,GO:1903555
A33: TRINITY_DN165847_c1_g1 | B33: 53.72059 | C33: -2.5162583 | D33: 0.48224582 | E33: -5.2177919 | F33: 1.8106873e-07 | G33: 8.1252811e-05 | H33: - | I33: - | J33: =VLOOKUP(A33,TableS4!A:J,10,FALSE) -> -
A34: TRINITY_DN28657_c0_g2 | B34: 54.251777 | C34: -2.3887518 | D34: 0.45322965 | E34: -5.2705108 | F34: 1.3604462e-07 | G34: 6.6590329e-05 | H34: K05747 | I34: ubiquitin-protein transferase activity | J34: =VLOOKUP(A34,TableS4!A:J,10,FALSE) -> -
A35: TRINITY_DN34915_c0_g2 | B35: 80.222133 | C35: -2.2494151 | D35: 0.37675204 | E35: -5.9705453 | F35: 2.3646187e-09 | G35: 2.3234417e-06 | H35: - | I35: - | J35: =VLOOKUP(A35,TableS4!A:J,10,FALSE) -> -
A36: TRINITY_DN206820_c1_g4 | B36: 91.553169 | C36: -2.2223886 | D36: 0.35640206 | E36: -6.2356223 | F36: 4.4998574e-10 | G36: 6.5755609e-07 | H36: - | I36: - | J36: =VLOOKUP(A36,TableS4!A:J,10,FALSE) -> -
A37: TRINITY_DN151915_c0_g2 | B37: 53.615692 | C37: -2.221817 | D37: 0.43946867 | E37: -5.0556892 | F37: 4.2883934e-07 | G37: 0.0001659457 | H37: - | I37: - | J37: =VLOOKUP(A37,TableS4!A:J,10,FALSE) -> -
A38: TRINITY_DN113910_c0_g2 | B38: 87.136358 | C38: -2.2130123 | D38: 0.36821975 | E38: -6.0100315 | F38: 1.8548728e-09 | G38: 1.9575778e-06 | H38: K18468 | I38: Plays a role in vesicular protein sorting | J38: =VLOOKUP(A38,TableS4!A:J,10,FALSE) -> -
A39: TRINITY_DN31863_c0_g1 | B39: 63.550702 | C39: -2.2115629 | D39: 0.47348706 | E39: -4.6707989 | F39: 3.0003051e-06 | G39: 0.00076171631 | I39: AAA domain | J39: =VLOOKUP(A39,TableS4!A:J,10,FALSE) -> -
A40: TRINITY_DN120573_c0_g1 | B40: 184.39497 | C40: -2.1467491 | D40: 0.27766063 | E40: -7.7315572 | F40: 1.0623893e-14 | G40: 5.0454637e-11 | J40: =VLOOKUP(A40,TableS4!A:J,10,FALSE) -> -
...

Sheet TableS4
A1: Table S4 | Heat treatment DEGs in Orbicella faveolata Symbiodinium A3 -2>logFC>2 padj<0.01. p value is obtained from a Wald test, and BH adjusted p-values are provided as padj (DESeq2).
A2: id | B2: baseMean | C2: log2FoldChange | D2: lfcSE | E2: stat | F2: pvalue | G2: padj | H2: KO | I2: Description | J2: GO
A3: TRINITY_DN310617_c0_g1 | B3: 127.31892 | C3: -2.6466205 | D3: 0.3157197 | E3: -8.3828171 | F3: 5.1675724e-17 | G3: 4.9083325e-13 | H3: K07238 | I3: ZIP family transporter | J3: - | S3: TRINITY_DN107447_c0_g1 | T3: GO:0003674,GO:0003824,GO:0004721,GO:0005488,GO:0005515,GO:0005575,GO:0005622,GO:0005623,GO:0005737,GO:0005819,GO:0005856,GO:0006464,GO:0006470,GO:0006793,GO:0006796,GO:0006807,GO:0008104,GO:0008150,GO:0008152,GO:0009987,GO:0015630,GO:0016311,GO:0016787,GO:0016788,GO:0016791,GO:0017157,GO:0019538,GO:0031072,GO:0032879,GO:0033036,GO:0033365,GO:0034613,GO:0036211,GO:0042578,GO:0043170,GO:0043226,GO:0043228,GO:0043229,GO:0043232,GO:0043412,GO:0044237,GO:0044238,GO:0044260,GO:0044267,GO:0044422,GO:0044424,GO:0044430,GO:0044446,GO:0044464,GO:0045920,GO:0048519,GO:0048523,GO:0050789,GO:0050794,GO:0051046,GO:0051048,GO:0051049,GO:0051051,GO:0051179,GO:0051641,GO:0051879,GO:0060627,GO:0065007,GO:0070727,GO:0071704,GO:0072686,GO:0140096,GO:1901564,GO:1903530,GO:1903531 | V3: TRINITY_DN107447_c0_g1 | W3: K04460 | Y3: TRINITY_DN107447_c0_g1 | Z3: Protein phosphatase 2A homologues, catalytic domain.
A4: TRINITY_DN389124_c0_g1 | B4: 65.5002 | C4: -3.7640988 | D4: 0.48227977 | E4: -7.8048035 | F4: 5.9594348e-15 | G4: 3.4876628e-11 | H4: K03654,K07114,K14949 | I4: Vault protein inter-alpha-trypsin domain | J4: - | S4: TRINITY_DN110231_c0_g2 | T4: GO:0003674,GO:0003824,GO:0005575,GO:0005622,GO:0005623,GO:0005737,GO:0006766,GO:0006775,GO:0008150,GO:0008152,GO:0008168,GO:0008171,GO:0009058,GO:0009110,GO:0009507,GO:0009536,GO:0009987,GO:0010189,GO:0016740,GO:0016741,GO:0018130,GO:0032259,GO:0042360,GO:0042362,GO:0043226,GO:0043227,GO:0043229,GO:0043231,GO:0044237,GO:0044249,GO:0044281,GO:0044283,GO:0044424,GO:0044444,GO:0044464,GO:0046483,GO:0050342,GO:0071704,GO:1901360,GO:1901362,GO:1901576,GO:1901615,GO:1901617 | V4: TRINITY_DN110231_c0_g2 | W4: K05928 | Y4: TRINITY_DN110231_c0_g2 | Z4: Belongs to the class I-like SAM-binding methyltransferase superfamily. gTMT family
A5: TRINITY_DN120573_c0_g1 | B5: 184.39497 | C5: -2.1467491 | D5: 0.27766063 | E5: -7.7315572 | F5: 1.0623893e-14 | G5: 5.0454637e-11 | H5: - | I5: - | J5: - | S5: TRINITY_DN11112_c0_g1 | T5: GO:0000139,GO:0000938,GO:0005575,GO:0005622,GO:0005623,GO:0005737,GO:0005739,GO:0005794,GO:0006810,GO:0006890,GO:0006950,GO:0006970,GO:0007009,GO:0008150,GO:0009266,GO:0009408,GO:0009628,GO:0009987,GO:0010256,GO:0010286,GO:0012505,GO:0016020,GO:0016043,GO:0016192,GO:0016197,GO:0016482,GO:0031090,GO:0031410,GO:0031982,GO:0031984,GO:0032991,GO:0042147,GO:0043226,GO:0043227,GO:0043229,GO:0043231,GO:0044422,GO:0044424,GO:0044431,GO:0044433,GO:0044444,GO:0044446,GO:0044464,GO:0046907,GO:0048193,GO:0050896,GO:0051179,GO:0051234,GO:0051641,GO:0051649,GO:0061024,GO:0071840,GO:0097708,GO:0098588,GO:0098791,GO:0099023 | V5: TRINITY_DN11112_c0_g1 | W5: K20299 | Y5: TRINITY_DN11112_c0_g1 | Z5: Vacuolar protein sorting-associated protein 53
A6: TRINITY_DN107864_c0_g2 | B6: 93.407768 | C6: -6.764265 | D6: 0.89161606 | E6: -7.5865222 | F6: 3.2860612e-14 | G6: 1.3376616e-10 | H6: - | I6: - | J6: - | S6: TRINITY_DN113910_c0_g1 | V6: TRINITY_DN113910_c0_g1 | W6: K18468 | Y6: TRINITY_DN113910_c0_g1 | Z6: Plays a role in vesicular protein sorting
A7: TRINITY_DN157834_c0_g3 | B7: 70.737752 | C7: -2.8462988 | D7: 0.40867229 | E7: -6.9647462 | F7: 3.2899642e-12 | G7: 8.9283363e-09 | H7: K19947 | I7: NADPH:sulfur oxidoreductase activity | J7: - | S7: TRINITY_DN113910_c0_g2 | V7: TRINITY_DN113910_c0_g2 | W7: K18468 | Y7: TRINITY_DN113910_c0_g2 | Z7: Plays a role in vesicular protein sorting
A8: TRINITY_DN430167_c0_g1 | B8: 71.384812 | C8: -2.6797981 | D8: 0.41695692 | E8: -6.4270383 | F8: 1.3011404e-10 | G8: 2.1809409e-07 | H8: - | I8: - | J8: - | S8: TRINITY_DN114728_c0_g2 | T8: GO:0000003,GO:0000075,GO:0000077,GO:0000082,GO:0000086,GO:0000122,GO:0000226,GO:0000278,GO:0000302,GO:0000307,GO:0000781,GO:0000793,GO:0000803,GO:0000805,GO:0000806,GO:0001654,GO:0002088,GO:0003674,GO:0003824,GO:0004672,GO:0004674,GO:0004693,GO:0005488,GO:0005515,GO:0005575,GO:0005622,GO:0005623,GO:0005634,GO:0005654,GO:0005667,GO:0005694,GO:0005737,GO:0005768,GO:0005813,GO:0005815,GO:0005819,GO:0005829,GO:0005856,GO:0006139,GO:0006259,GO:0006260,GO:0006275,GO:0006281,GO:0006325,GO:0006355,GO:0006357,GO:0006464,GO:0006468,GO:0006725,GO:0006793,GO:0006796,GO:0006807,GO:0006810,GO:0006811,GO:0006812,GO:0006813,GO:0006950,GO:0006974,GO:0006977,GO:0006979,GO:0006996,GO:0007010,GO:0007017,GO:0007049,GO:0007093,GO:0007098,GO:0007099,GO:0007154,GO:0007165,GO:0007264,GO:0007265,GO:0007275,GO:0007346,GO:0007423,GO:0008150,GO:0008152,GO:0008283,GO:0008284,GO:0009058,GO:0009059,GO:0009628,GO:0009636,GO:0009719,GO:0009725,GO:0009889,GO:0009890,GO:0009891,GO:0009892,GO:0009893,GO:0009966,GO:0009967,GO:0009987,GO:0010033,GO:0010035,GO:0010038,GO:0010243,GO:0010389,GO:0010468,GO:0010556,GO:0010557,GO:0010558,GO:0010564,GO:0010604,GO:0010605,GO:0010628,GO:0010629,GO:0010646,GO:0010647,GO:0010948,GO:0012505,GO:0014070,GO:0014074,GO:0015030,GO:0015630,GO:0015672,GO:0016043,GO:0016301,GO:0016310,GO:0016569,GO:0016570,GO:0016572,GO:0016604,GO:0016740,GO:0016772,GO:0016773,GO:0018105,GO:0018193,GO:0018209,GO:0019219,GO:0019222,GO:0019538,GO:0019904,GO:0022402,GO:0022414,GO:0022607,GO:0023051,GO:0023052,GO:0023056,GO:0030001,GO:0030154,GO:0030174,GO:0030330,GO:0030332,GO:0031023,GO:0031099,GO:0031100,GO:0031323,GO:0031324,GO:0031325,GO:0031326,GO:0031327,GO:0031328,GO:0031410,GO:0031570,GO:0031571,GO:0031974,GO:0031981,GO:0031982,GO:0032298,GO:0032355,GO:0032501,GO:0032502,GO:0032868,GO:0032869,GO:0032870,GO:0032991,GO:0033554,GO:0033993,GO:0034599,GO:0034614,GO:0034641,GO:0034645,GO:0035556,GO:0035690,GO:0036211,GO:0042127,GO:0042221,GO:0042493,GO:0042770,GO:0043010,GO:0043170,GO:0043226,GO:0043227,GO:0043228,GO:0043229,GO:0043231,GO:0043232,GO:0043233,GO:0043412,GO:0043434,GO:0044085,GO:0044237,GO:0044238,GO:0044249,GO:0044260,GO:0044267,GO:0044422,GO:0044424,GO:0044427,GO:0044428,GO:0044430,GO:0044444,GO:0044446,GO:0044451,GO:0044464,GO:0044770,GO:0044772,GO:0044773,GO:0044774,GO:0044783,GO:0044819,GO:0044839,GO:0044843,GO:0044877,GO:0045023,GO:0045471,GO:0045740,GO:0045786,GO:0045787,GO:0045892,GO:0045893,GO:0045930,GO:0045934,GO:0045935,GO:0046425,GO:0046427,GO:0046483,GO:0046677,GO:0046683,GO:0046686,GO:0048513,GO:0048518,GO:0048519,GO:0048522,GO:0048523,GO:0048583,GO:0048584,GO:0048731,GO:0048856,GO:0048869,GO:0050789,GO:0050794,GO:0050896,GO:0051052,GO:0051054,GO:0051171,GO:0051172,GO:0051173,GO:0051179,GO:0051234,GO:0051252,GO:0051253,GO:0051254,GO:0051276,GO:0051298,GO:0051321,GO:0051445,GO:0051591,GO:0051602,GO:0051716,GO:0051726,GO:0060255,GO:0060968,GO:0061695,GO:0065007,GO:0070013,GO:0070887,GO:0070925,GO:0071156,GO:0071158,GO:0071241,GO:0071310,GO:0071375,GO:0071417,GO:0071495,GO:0071704,GO:0071731,GO:0071732,GO:0071840,GO:0072331,GO:0072395,GO:0072401,GO:0072413,GO:0072422,GO:0072431,GO:0072686,GO:0080090,GO:0090068,GO:0090304,GO:0090329,GO:0097123,GO:0097124,GO:0097134,GO:0097135,GO:0097305,GO:0097366,GO:0097472,GO:0097708,GO:0098534,GO:0098687,GO:0140096,GO:1901360,GO:1901564,GO:1901576,GO:1901652,GO:1901653,GO:1901698,GO:1901699,GO:1901700,GO:1901701,GO:1901796,GO:1901987,GO:1901988,GO:1901990,GO:1901991,GO:1902170,GO:1902400,GO:1902402,GO:1902403,GO:1902494,GO:1902531,GO:1902533,GO:1902554,GO:1902679,GO:1902680,GO:1902749,GO:1902806,GO:1902807,GO:1902911,GO:1903047,GO:1903506,GO:1903507,GO:1903508,GO:1904892,GO:1904894,GO:1990234,GO:2000045,GO:2000105,GO:2000112,GO:2000113,GO:2000134,GO:2000241,GO:2001141 | V8: TRINITY_DN114728_c0_g2 | W8: K02088,K02206 | Y8: TRINITY_DN114728_c0_g2 | Z8: cyclin-dependent protein serine/threonine kinase activity
A9: TRINITY_DN69788_c0_g2 | B9: 146.24651 | C9: -10.470373 | D9: 1.650585 | E9: -6.3434315 | F9: 2.2470287e-10 | G9: 3.5571713e-07 | H9: - | I9: - | J9: - | S9: TRINITY_DN120573_c0_g1 | V9: TRINITY_DN120573_c0_g1 | Y9: TRINITY_DN120573_c0_g1
A10: TRINITY_DN206820_c1_g4 | B10: 91.553169 | C10: -2.2223886 | D10: 0.35640206 | E10: -6.2356223 | F10: 4.4998574e-10 | G10: 6.5755609e-07 | H10: - | I10: - | J10: - | S10: TRINITY_DN123209_c0_g1 | T10: GO:0000719,GO:0003674,GO:0003824,GO:0003904,GO:0003913,GO:0006139,GO:0006259,GO:0006281,GO:0006290,GO:0006725,GO:0006807,GO:0006950,GO:0006974,GO:0008150,GO:0008152,GO:0009987,GO:0016829,GO:0016830,GO:0033554,GO:0034641,GO:0043170,GO:0044237,GO:0044238,GO:0044260,GO:0046483,GO:0050896,GO:0051716,GO:0071704,GO:0090304,GO:0140097,GO:1901360 | V10: TRINITY_DN123209_c0_g1 | W10: K01669 | Y10: TRINITY_DN123209_c0_g1 | Z10: DNA photolyase
A11: TRINITY_DN122184_c0_g2 | B11: 58.617122 | C11: -2.8365078 | D11: 0.46035759 | E11: -6.1615314 | F11: 7.2044781e-10 | G11: 9.3314365e-07 | H11: - | I11: - | J11: - | S11: TRINITY_DN123231_c0_g4 | T11: GO:0005575,GO:0005622,GO:0005623,GO:0005737,GO:0005739,GO:0006996,GO:0007005,GO:0008150,GO:0009987,GO:0016043,GO:0043226,GO:0043227,GO:0043229,GO:0043231,GO:0044424,GO:0044444,GO:0044464,GO:0071840 | V11: TRINITY_DN123231_c0_g4 | W11: K00471 | Y11: TRINITY_DN123231_c0_g4 | Z11: gamma-butyrobetaine dioxygenase activity
A12: TRINITY_DN157925_c0_g3 | B12: 76.905348 | C12: -2.5252777 | D12: 0.41837772 | E12: -6.0358801 | F12: 1.5809864e-09 | G12: 1.7666748e-06 | H12: - | I12: Calcium-dependent protein kinase | J12: GO:0000165,GO:0000187,GO:0001817,GO:0001932,GO:0001934,GO:0002218,GO:0002221,GO:0002224,GO:0002237,GO:0002253,GO:0002376,GO:0002682,GO:0002684,GO:0002757,GO:0002758,GO:0002764,GO:0003674,GO:0003824,GO:0004672,GO:0004674,GO:0004683,GO:0005488,GO:0005515,GO:0005516,GO:0005575,GO:0005622,GO:0005623,GO:0005634,GO:0005654,GO:0005737,GO:0005813,GO:0005815,GO:0005829,GO:0005856,GO:0006082,GO:0006464,GO:0006468,GO:0006690,GO:0006691,GO:0006793,GO:0006796,GO:0006807,GO:0006810,GO:0006897,GO:0006907,GO:0006950,GO:0006952,GO:0006954,GO:0006974,GO:0007154,GO:0007165,GO:0007166,GO:0007167,GO:0007169,GO:0008150,GO:0008152,GO:0009605,GO:0009607,GO:0009617,GO:0009892,GO:0009893,GO:0009894,GO:0009895,GO:0009931,GO:0009966,GO:0009967,GO:0009987,GO:0010033,GO:0010468,GO:0010562,GO:0010604,GO:0010605,GO:0010608,GO:0010628,GO:0010646,GO:0010647,GO:0010857,GO:0015630,GO:0016192,GO:0016301,GO:0016310,GO:0016740,GO:0016772,GO:0016773,GO:0018105,GO:0018193,GO:0018209,GO:0019219,GO:0019220,GO:0019222,GO:0019538,GO:0019752,GO:0019899,GO:0019900,GO:0019901,GO:0023014,GO:0023051,GO:0023052,GO:0023056,GO:0031323,GO:0031324,GO:0031325,GO:0031329,GO:0031330,GO:0031347,GO:0031349,GO:0031399,GO:0031401,GO:0031974,GO:0031981,GO:0032147,GO:0032268,GO:0032270,GO:0032496,GO:0032675,GO:0032680,GO:0033554,GO:0033674,GO:0033993,GO:0034097,GO:0035556,GO:0035924,GO:0036211,GO:0042221,GO:0042325,GO:0042327,GO:0043085,GO:0043170,GO:0043207,GO:0043226,GO:0043227,GO:0043228,GO:0043229,GO:0043231,GO:0043232,GO:0043233,GO:0043405,GO:0043406,GO:0043408,GO:0043410,GO:0043412,GO:0043436,GO:0043487,GO:0043488,GO:0043489,GO:0043549,GO:0044093,GO:0044237,GO:0044238,GO:0044260,GO:0044267,GO:0044281,GO:0044351,GO:0044422,GO:0044424,GO:0044428,GO:0044430,GO:0044444,GO:0044446,GO:0044464,GO:0045088,GO:0045089,GO:0045859,GO:0045860,GO:0045934,GO:0045937,GO:0046777,GO:0048010,GO:0048255,GO:0048518,GO:0048519,GO:0048522,GO:0048523,GO:0048583,GO:0048584,GO:0050776,GO:0050778,GO:0050789,GO:0050790,GO:0050794,GO:0050896,GO:0051019,GO:0051171,GO:0051172,GO:0051173,GO:0051174,GO:0051179,GO:0051234,GO:0051239,GO:0051246,GO:0051247,GO:0051252,GO:0051253,GO:0051338,GO:0051347,GO:0051704,GO:0051707,GO:0051716,GO:0060255,GO:0061013,GO:0065007,GO:0065008,GO:0065009,GO:0070013,GO:0070848,GO:0070887,GO:0070935,GO:0071310,GO:0071363,GO:0071704,GO:0071900,GO:0071902,GO:0080090,GO:0080134,GO:0080135,GO:0098657,GO:0140096,GO:1900034,GO:1901564,GO:1901568,GO:1901700,GO:1902369,GO:1902373,GO:1902531,GO:1902533,GO:1903311,GO:1903312,GO:1903555 | S12: TRINITY_DN123666_c0_g1 | V12: TRINITY_DN123666_c0_g1 | Y12: TRINITY_DN123666_c0_g1
A13: TRINITY_DN113910_c0_g2 | B13: 87.136358 | C13: -2.2130123 | D13: 0.36821975 | E13: -6.0100315 | F13: 1.8548728e-09 | G13: 1.9575778e-06 | H13: K18468 | I13: Plays a role in vesicular protein sorting | J13: - | S13: TRINITY_DN12366_c0_g1 | V13: TRINITY_DN12366_c0_g1 | Y13: TRINITY_DN12366_c0_g1 | Z13: regulation of endocannabinoid signaling pathway
A14: TRINITY_DN225772_c0_g1 | B14: 62.960565 | C14: -3.1256838 | D14: 0.52047759 | E14: -6.0054148 | F14: 1.9084332e-09 | G14: 1.9774838e-06 | H14: - | I14: - | J14: - | S14: TRINITY_DN12554_c0_g2 | V14: TRINITY_DN12554_c0_g2 | Y14: TRINITY_DN12554_c0_g2 | Z14: Fic/DOC family
A15: TRINITY_DN34915_c0_g2 | B15: 80.222133 | C15: -2.2494151 | D15: 0.37675204 | E15: -5.9705453 | F15: 2.3646187e-09 | G15: 2.3234417e-06 | H15: - | I15: - | J15: - | S15: TRINITY_DN128147_c0_g2 | V15: TRINITY_DN128147_c0_g2 | Y15: TRINITY_DN128147_c0_g2 | Z15: Dynamin, GTPase
A16: TRINITY_DN106609_c0_g2 | B16: 79.043755 | C16: -2.0073069 | D16: 0.35377799 | E16: -5.6739167 | F16: 1.3956904e-08 | G16: 9.9425497e-06 | H16: - | I16: - | J16: - | S16: TRINITY_DN136577_c0_g2 | V16: TRINITY_DN136577_c0_g2 | Y16: TRINITY_DN136577_c0_g2 | Z16: calcium ion binding
A17: TRINITY_DN19131_c0_g1 | B17: 125.82011 | C17: -10.252471 | D17: 1.9069713 | E17: -5.376311 | F17: 7.6027427e-08 | G17: 4.2420683e-05 | H17: - | I17: RNA-binding protein mei2 homologue | J17: - | S17: TRINITY_DN139147_c1_g1 | V17: TRINITY_DN139147_c1_g1 | W17: K06999 | Y17: TRINITY_DN139147_c1_g1 | Z17: Phospholipase/Carboxylesterase
A18: TRINITY_DN128742_c0_g3 | B18: 43.364248 | C18: -2.6703418 | D18: 0.49714702 | E18: -5.3713322 | F18: 7.8157076e-08 | G18: 4.2420683e-05 | H18: - | I18: - | J18: - | S18: TRINITY_DN14835_c0_g1 | V18: TRINITY_DN14835_c0_g1 | Y18: TRINITY_DN14835_c0_g1
A19: TRINITY_DN141779_c0_g5 | B19: 34.69274 | C19: -5.9432244 | D19: 1.1199064 | E19: -5.3068941 | F19: 1.1150891e-07 | G19: 5.8301769e-05 | H19: - | I19: - | J19: - | S19: TRINITY_DN154712_c0_g1 | V19: TRINITY_DN154712_c0_g1 | Y19: TRINITY_DN154712_c0_g1 | Z19: Polycystin cation channel
A20: TRINITY_DN28657_c0_g2 | B20: 54.251777 | C20: -2.3887518 | D20: 0.45322965 | E20: -5.2705108 | F20: 1.3604462e-07 | G20: 6.6590329e-05 | H20: K05747 | I20: ubiquitin-protein transferase activity | J20: - | S20: TRINITY_DN157834_c0_g3 | V20: TRINITY_DN157834_c0_g3 | W20: K19947 | Y20: TRINITY_DN157834_c0_g3 | Z20: NADPH:sulfur oxidoreductase activity
A21: TRINITY_DN48606_c0_g1 | B21: 26.95193 | C21: -8.0330009 | D21: 1.5328869 | E21: -5.2404393 | F21: 1.6019478e-07 | G21: 7.4223579e-05 | H21: K01070,K09795 | I21: Serine hydrolase involved in the detoxification of formaldehyde | J21: - | S21: TRINITY_DN157925_c0_g3 | T21: GO:0000165,GO:0000187,GO:0001817,GO:0001932,GO:0001934,GO:0002218,GO:0002221,GO:0002224,GO:0002237,GO:0002253,GO:0002376,GO:0002682,GO:0002684,GO:0002757,GO:0002758,GO:0002764,GO:0003674,GO:0003824,GO:0004672,GO:0004674,GO:0004683,GO:0005488,GO:0005515,GO:0005516,GO:0005575,GO:0005622,GO:0005623,GO:0005634,GO:0005654,GO:0005737,GO:0005813,GO:0005815,GO:0005829,GO:0005856,GO:0006082,GO:0006464,GO:0006468,GO:0006690,GO:0006691,GO:0006793,GO:0006796,GO:0006807,GO:0006810,GO:0006897,GO:0006907,GO:0006950,GO:0006952,GO:0006954,GO:0006974,GO:0007154,GO:0007165,GO:0007166,GO:0007167,GO:0007169,GO:0008150,GO:0008152,GO:0009605,GO:0009607,GO:0009617,GO:0009892,GO:0009893,GO:0009894,GO:0009895,GO:0009931,GO:0009966,GO:0009967,GO:0009987,GO:0010033,GO:0010468,GO:0010562,GO:0010604,GO:0010605,GO:0010608,GO:0010628,GO:0010646,GO:0010647,GO:0010857,GO:0015630,GO:0016192,GO:0016301,GO:0016310,GO:0016740,GO:0016772,GO:0016773,GO:0018105,GO:0018193,GO:0018209,GO:0019219,GO:0019220,GO:0019222,GO:0019538,GO:0019752,GO:0019899,GO:0019900,GO:0019901,GO:0023014,GO:0023051,GO:0023052,GO:0023056,GO:0031323,GO:0031324,GO:0031325,GO:0031329,GO:0031330,GO:0031347,GO:0031349,GO:0031399,GO:0031401,GO:0031974,GO:0031981,GO:0032147,GO:0032268,GO:0032270,GO:0032496,GO:0032675,GO:0032680,GO:0033554,GO:0033674,GO:0033993,GO:0034097,GO:0035556,GO:0035924,GO:0036211,GO:0042221,GO:0042325,GO:0042327,GO:0043085,GO:0043170,GO:0043207,GO:0043226,GO:0043227,GO:0043228,GO:0043229,GO:0043231,GO:0043232,GO:0043233,GO:0043405,GO:0043406,GO:0043408,GO:0043410,GO:0043412,GO:0043436,GO:0043487,GO:0043488,GO:0043489,GO:0043549,GO:0044093,GO:0044237,GO:0044238,GO:0044260,GO:0044267,GO:0044281,GO:0044351,GO:0044422,GO:0044424,GO:0044428,GO:0044430,GO:0044444,GO:0044446,GO:0044464,GO:0045088,GO:0045089,GO:0045859,GO:0045860,GO:0045934,GO:0045937,GO:0046777,GO:0048010,GO:0048255,GO:0048518,GO:0048519,GO:0048522,GO:0048523,GO:0048583,GO:0048584,GO:0050776,GO:0050778,GO:0050789,GO:0050790,GO:0050794,GO:0050896,GO:0051019,GO:0051171,GO:0051172,GO:0051173,GO:0051174,GO:0051179,GO:0051234,GO:0051239,GO:0051246,GO:0051247,GO:0051252,GO:0051253,GO:0051338,GO:0051347,GO:0051704,GO:0051707,GO:0051716,GO:0060255,GO:0061013,GO:0065007,GO:0065008,GO:0065009,GO:0070013,GO:0070848,GO:0070887,GO:0070935,GO:0071310,GO:0071363,GO:0071704,GO:0071900,GO:0071902,GO:0080090,GO:0080134,GO:0080135,GO:0098657,GO:0140096,GO:1900034,GO:1901564,GO:1901568,GO:1901700,GO:1902369,GO:1902373,GO:1902531,GO:1902533,GO:1903311,GO:1903312,GO:1903555 | V21: TRINITY_DN157925_c0_g3 | Y21: TRINITY_DN157925_c0_g3 | Z21: Calcium-dependent protein kinase
A22: TRINITY_DN29380_c0_g1 | B22: 26.953588 | C22: -8.0209479 | D22: 1.5334177 | E22: -5.2307653 | F22: 1.6880975e-07 | G22: 7.7584416e-05 | H22: - | I22: - | J22: - | S22: TRINITY_DN159490_c1_g2 | V22: TRINITY_DN159490_c1_g2 | Y22: TRINITY_DN159490_c1_g2 | Z22: Sulfotransferase family
A23: TRINITY_DN165847_c1_g1 | B23: 53.72059 | C23: -2.5162583 | D23: 0.48224582 | E23: -5.2177919 | F23: 1.8106873e-07 | G23: 8.1252811e-05 | H23: - | I23: - | J23: - | S23: TRINITY_DN169098_c0_g1 | T23: GO:0000041,GO:0003674,GO:0005215,GO:0005575,GO:0005623,GO:0005886,GO:0005887,GO:0006810,GO:0006811,GO:0006812,GO:0008150,GO:0008324,GO:0015075,GO:0015099,GO:0015318,GO:0015675,GO:0016020,GO:0016021,GO:0022857,GO:0022890,GO:0030001,GO:0031224,GO:0031226,GO:0034220,GO:0035444,GO:0044425,GO:0044459,GO:0044464,GO:0044750,GO:0046873,GO:0046915,GO:0051179,GO:0051234,GO:0055085,GO:0071944,GO:0098655,GO:0098657,GO:0098659,GO:0098660,GO:0098662,GO:0098716,GO:0098739,GO:0099587 | V23: TRINITY_DN169098_c0_g1 | W23: K07241 | Y23: TRINITY_DN169098_c0_g1 | Z23: High-affinity nickel-transport protein
A24: TRINITY_DN198015_c0_g4 | B24: 33.226877 | C24: -3.1357024 | D24: 0.61249216 | E24: -5.1195796 | F24: 3.0621757e-07 | G24: 0.00013023388 | H24: - | I24: - | J24: - | S24: TRINITY_DN187798_c1_g1 | V24: TRINITY_DN187798_c1_g1 | Y24: TRINITY_DN187798_c1_g1 | Z24: Protein tyrosine kinase
A25: TRINITY_DN69828_c0_g1 | B25: 42.542187 | C25: -2.5762215 | D25: 0.50356781 | E25: -5.1159375 | F25: 3.1218636e-07 | G25: 0.00013178889 | H25: - | I25: - | J25: - | S25: TRINITY_DN191166_c0_g3 | T25: GO:0003674,GO:0003824,GO:0005575,GO:0005622,GO:0005623,GO:0005737,GO:0005829,GO:0005911,GO:0006139,GO:0006725,GO:0006793,GO:0006807,GO:0006810,GO:0008150,GO:0008152,GO:0009058,GO:0009225,GO:0009226,GO:0009506,GO:0009812,GO:0009813,GO:0009914,GO:0009966,GO:0009987,GO:0010253,GO:0010280,GO:0010315,GO:0010646,GO:0010817,GO:0010928,GO:0016829,GO:0016835,GO:0016836,GO:0018130,GO:0019438,GO:0023051,GO:0030054,GO:0030154,GO:0032502,GO:0033478,GO:0034641,GO:0034654,GO:0042127,GO:0042440,GO:0044237,GO:0044238,GO:0044249,GO:0044271,GO:0044281,GO:0044424,GO:0044444,GO:0044464,GO:0046148,GO:0046483,GO:0048583,GO:0048869,GO:0050377,GO:0050789,GO:0050794,GO:0051179,GO:0051234,GO:0051552,GO:0051553,GO:0051554,GO:0051555,GO:0055044,GO:0055086,GO:0060918,GO:0065007,GO:0065008,GO:0071704,GO:1901135,GO:1901137,GO:1901360,GO:1901362,GO:1901576,GO:1901615,GO:1901617 | V25: TRINITY_DN191166_c0_g3 | W25: K12450 | Y25: TRINITY_DN191166_c0_g3 | Z25: rhamnose biosynthetic enzyme
A26: TRINITY_DN54874_c0_g2 | B26: 24.308711 | C26: -7.8828991 | D26: 1.5431775 | E26: -5.1082257 | F26: 3.2519814e-07 | G26: 0.00013627237 | H26: - | I26: - | J26: - | S26: TRINITY_DN19131_c0_g1 | V26: TRINITY_DN19131_c0_g1 | Y26: TRINITY_DN19131_c0_g1 | Z26: RNA-binding protein mei2 homologue
A27: TRINITY_DN6716_c0_g1 | B27: 23.892919 | C27: -7.8666177 | D27: 1.5502967 | E27: -5.0742658 | F27: 3.889949e-07 | G27: 0.00015595869 | H27: K06641 | I27: Belongs to the protein kinase superfamily | J27: GO:0000075,GO:0000077,GO:0003674,GO:0003824,GO:0004672,GO:0004674,GO:0004683,GO:0005488,GO:0005515,GO:0005516,GO:0005575,GO:0005622,GO:0005623,GO:0005634,GO:0006139,GO:0006259,GO:0006260,GO:0006261,GO:0006275,GO:0006464,GO:0006468,GO:0006725,GO:0006793,GO:0006796,GO:0006807,GO:0006950,GO:0006974,GO:0006979,GO:0007154,GO:0007165,GO:0008150,GO:0008152,GO:0008156,GO:0009058,GO:0009059,GO:0009889,GO:0009890,GO:0009892,GO:0009987,GO:0010556,GO:0010558,GO:0010605,GO:0016301,GO:0016310,GO:0016740,GO:0016772,GO:0016773,GO:0018105,GO:0018107,GO:0018193,GO:0018209,GO:0018210,GO:0019219,GO:0019222,GO:0019538,GO:0023052,GO:0031323,GO:0031324,GO:0031326,GO:0031327,GO:0031570,GO:0033554,GO:0034599,GO:0034641,GO:0034645,GO:0035556,GO:0036211,GO:0042221,GO:0043170,GO:0043226,GO:0043227,GO:0043229,GO:0043231,GO:0043412,GO:0044237,GO:0044238,GO:0044249,GO:0044260,GO:0044267,GO:0044424,GO:0044464,GO:0045005,GO:0045786,GO:0045934,GO:0046483,GO:0048478,GO:0048519,GO:0048523,GO:0050789,GO:0050794,GO:0050896,GO:0051052,GO:0051053,GO:0051171,GO:0051172,GO:0051716,GO:0051726,GO:0060255,GO:0065007,GO:0070887,GO:0071704,GO:0080090,GO:0090304,GO:0090329,GO:0140096,GO:1901360,GO:1901564,GO:1901576,GO:2000104,GO:2000112,GO:2000113 | S27: TRINITY_DN199776_c0_g1 | V27: TRINITY_DN199776_c0_g1 | W27: K20444 | Y27: TRINITY_DN199776_c0_g1 | Z27: Sulfotransferase family
A28: TRINITY_DN68465_c0_g1 | B28: 24.203106 | C28: -7.890102 | D28: 1.5552742 | E28: -5.0731259 | F28: 3.9133344e-07 | G28: 0.00015595869 | H28: - | I28: - | J28: - | S28: TRINITY_DN203859_c0_g2 | V28: TRINITY_DN203859_c0_g2 | Y28: TRINITY_DN203859_c0_g2 | Z28: macromolecule localization
A29: TRINITY_DN151915_c0_g2 | B29: 53.615692 | C29: -2.221817 | D29: 0.43946867 | E29: -5.0556892 | F29: 4.2883934e-07 | G29: 0.0001659457 | H29: - | I29: - | J29: - | S29: TRINITY_DN209900_c0_g2 | V29: TRINITY_DN209900_c0_g2 | Y29: TRINITY_DN209900_c0_g2
A30: TRINITY_DN7731_c0_g2 | B30: 22.987931 | C30: -7.794574 | D30: 1.5494175 | E30: -5.030648 | F30: 4.8882494e-07 | G30: 0.00017972989 | H30: - | I30: - | J30: - | S30: TRINITY_DN211470_c1_g5 | T30: GO:0000154,GO:0000455,GO:0001522,GO:0003674,GO:0003824,GO:0005575,GO:0005622,GO:0005623,GO:0005737,GO:0005829,GO:0006139,GO:0006364,GO:0006396,GO:0006399,GO:0006400,GO:0006725,GO:0006807,GO:0008033,GO:0008150,GO:0008152,GO:0009451,GO:0009982,GO:0009987,GO:0010467,GO:0016070,GO:0016072,GO:0016853,GO:0016866,GO:0022613,GO:0031118,GO:0031119,GO:0034470,GO:0034641,GO:0034660,GO:0042254,GO:0043170,GO:0043412,GO:0044085,GO:0044237,GO:0044238,GO:0044424,GO:0044444,GO:0044464,GO:0046483,GO:0071704,GO:0071840,GO:0090304,GO:1901360 | V30: TRINITY_DN211470_c1_g5 | W30: K06178,K06182,K06183 | Y30: TRINITY_DN211470_c1_g5 | Z30: Belongs to the pseudouridine synthase RsuA family
A31: TRINITY_DN135274_c0_g1 | B31: 22.340327 | C31: -7.7507057 | D31: 1.5537625 | E31: -4.9883464 | F31: 6.0898287e-07 | G31: 0.00021827631 | H31: - | I31: - | J31: - | S31: TRINITY_DN215887_c0_g5 | T31: GO:0003674,GO:0003824,GO:0005215,GO:0005575,GO:0005622,GO:0005623,GO:0005886,GO:0006139,GO:0006163,GO:0006164,GO:0006725,GO:0006753,GO:0006754,GO:0006793,GO:0006796,GO:0006807,GO:0006810,GO:0006811,GO:0006812,GO:0008150,GO:0008152,GO:0008324,GO:0009058,GO:0009117,GO:0009123,GO:0009124,GO:0009126,GO:0009127,GO:0009141,GO:0009142,GO:0009144,GO:0009145,GO:0009150,GO:0009152,GO:0009156,GO:0009161,GO:0009165,GO:0009167,GO:0009168,GO:0009199,GO:0009201,GO:0009205,GO:0009206,GO:0009259,GO:0009260,GO:0009987,GO:0015075,GO:0015077,GO:0015078,GO:0015318,GO:0015399,GO:0015405,GO:0015672,GO:0015985,GO:0015986,GO:0016020,GO:0016462,GO:0016469,GO:0016787,GO:0016817,GO:0016818,GO:0016887,GO:0017111,GO:0017144,GO:0018130,GO:0019438,GO:0019637,GO:0019693,GO:0019829,GO:0022804,GO:0022853,GO:0022857,GO:0022890,GO:0032991,GO:0033178,GO:0034220,GO:0034641,GO:0034654,GO:0036442,GO:0042623,GO:0042625,GO:0042626,GO:0043492,GO:0044237,GO:0044238,GO:0044249,GO:0044271,GO:0044281,GO:0044424,GO:0044425,GO:0044459,GO:0044464,GO:0044769,GO:0045259,GO:0045260,GO:0045261,GO:0045262,GO:0046034,GO:0046390,GO:0046483,GO:0046933,GO:0046961,GO:0051179,GO:0051234,GO:0055085,GO:0055086,GO:0071704,GO:0071944,GO:0072521,GO:0072522,GO:0090407,GO:0090662,GO:0098655,GO:0098660,GO:0098662,GO:0098796,GO:0098797,GO:0099131,GO:0099132,GO:1901135,GO:1901137,GO:1901293,GO:1901360,GO:1901362,GO:1901564,GO:1901566,GO:1901576,GO:1902600 | V31: TRINITY_DN215887_c0_g5 | W31: K02112 | Y31: TRINITY_DN215887_c0_g5 | Z31: Produces ATP from ADP in the presence of a proton gradient across the membrane. The catalytic sites are hosted primarily by the beta subunits
